#VRML_SIM R2023b utf8
# license: Apache License 2.0
# license url: http://www.apache.org/licenses/LICENSE-2.0
# Hexapod robot simplified model made for KNR Bionik Hexapod Project

PROTO ElkapodSimplified [
  field  SFVec3f     translation     0 0 0
  field  SFRotation  rotation        0 0 1 0
  field  SFString    name            "Elkapod"                               # Is `Robot.name`.
  field  SFString    controller      "void"                                  # Is `Robot.controller`.
  field  MFString    controllerArgs  []                                      # Is `Robot.controllerArgs`.
  field  SFString    customData      ""                                      # Is `Robot.customData`.
  field  SFBool      supervisor      FALSE                                   # Is `Robot.supervisor`.
  field  SFBool      synchronization TRUE                                    # Is `Robot.synchronization`.
  field  SFBool      selfCollision   TRUE                                    # Is `Robot.selfCollision`.
]
{
  Robot {
    translation IS translation
    rotation IS rotation
    controller IS controller
    controllerArgs IS controllerArgs
    customData IS customData
    supervisor IS supervisor
    synchronization IS synchronization
    selfCollision IS selfCollision
    children [
    DEF HeadTranslation Pose {
      translation 0 0.15 0
      children [
        DEF Head Shape {
          appearance PBRAppearance {
            baseColor 0.144442 0.568017 0.833341
            metalness 0
          }
          geometry Cylinder {
            height 0.06
            radius 0.03
          }
        }
      ]
    }
    DEF L6J1 HingeJoint {
      jointParameters HingeJointParameters {
        position 3.14
        axis 0 0 1
        anchor -0.1 -0.15 0
      }
      device [
        RotationalMotor {
          name "Servo61"
        }
      ]
      endPoint Solid {
        translation -0.1 -0.15 -1.4268099999999993e-05
        rotation 0.0005622220406647018 0.7071079684969854 0.7071053703617612 3.1404662348267345
        children [
          DEF MountServoTransform Pose {
            rotation 1 0 0 -1.5708
            children [
              DEF MountPoint Shape {
                appearance PBRAppearance {
                  baseColor 0.380392 0.207843 0.513726
                  metalness 0
                }
                geometry Cylinder {
                  height 0.06
                  radius 0.01
                }
              }
            ]
          }
          DEF A1_Transform Pose {
            translation 0.0315 0 0
            children [
              DEF A1 Shape {
                appearance PBRAppearance {
                  baseColor 0.898039 0.647059 0.0392157
                  metalness 0
                }
                geometry Box {
                  size 0.063 0.02 0.02
                }
              }
            ]
          }
          DEF L6J2 HingeJoint {
            jointParameters HingeJointParameters {
              axis 0 0 1
              anchor 0.063 0 0
            }
            device [
              DEF Servo12 RotationalMotor {
                name "Servo62"
              }
            ]
            endPoint Solid {
              translation 0.06300000000000001 -5.240473550862772e-18 0
              children [
                DEF A2_Transform Pose {
                  translation 0.045 0 0
                  children [
                    DEF A2 Shape {
                      appearance PBRAppearance {
                        baseColor 1 0.470588 0
                        metalness 0
                      }
                      geometry Box {
                        size 0.09 0.02 0.02
                      }
                    }
                  ]
                }
                DEF L6J3 HingeJoint {
                  jointParameters HingeJointParameters {
                    axis 0 0 1
                    anchor 0.09 0 0
                  }
                  device [
                    DEF Servo13 RotationalMotor {
                      name "Servo63"
                    }
                  ]
                  endPoint Solid {
                    translation 0.09 0 0
                    children [
                      DEF FootTransform Pose {
                        translation 0.215 0 0
                        children [
                          DEF L1FootSphere Shape {
                            appearance PBRAppearance {
                              baseColor 0.141176 0.121569 0.192157
                              roughness 1
                              metalness 0
                            }
                            geometry Sphere {
                              radius 0.015
                            }
                          }
                        ]
                      }
                      DEF A3_Transform Pose {
                        translation 0.1075 0 0
                        children [
                          DEF A3 Shape {
                            appearance PBRAppearance {
                              baseColor 0.14902 0.635294 0.411765
                              metalness 0
                            }
                            geometry Box {
                              size 0.215 0.02 0.02
                            }
                          }
                        ]
                      }
                      Shape {
                        appearance PBRAppearance {
                          baseColor 0.380392 0.207843 0.513726
                          metalness 0
                        }
                        geometry Cylinder {
                          height 0.025
                          radius 0.0125
                        }
                      }
                    ]
                    boundingObject USE FootTransform
                    physics Physics {
                    }
                  }
                }
                Shape {
                  appearance PBRAppearance {
                    baseColor 0.380392 0.207843 0.513726
                    metalness 0
                  }
                  geometry Cylinder {
                    height 0.025
                    radius 0.0125
                  }
                }
              ]
              boundingObject USE A2_Transform
              physics Physics {
              }
            }
          }
        ]
        name "solid(11)"
        boundingObject USE A1_Transform
        physics Physics {
        }
      }
    }
    DEF L5J1 HingeJoint {
      jointParameters HingeJointParameters {
        position 3.14
        axis 0 0 1
        anchor -0.1 0 0
      }
      device [
        RotationalMotor {
          name "Servo51"
        }
      ]
      endPoint Solid {
        translation -0.100119 -7.180457112552314e-19 -1.42681e-05
        rotation 0.0005622220463405306 0.7071079756357184 0.7071053632229972 3.140466234838101
        children [
          DEF L2MountServoTransform Pose {
            rotation 1 0 0 -1.5708
            children [
              DEF MountPoint Shape {
                appearance PBRAppearance {
                  baseColor 0.380392 0.207843 0.513726
                  metalness 0
                }
                geometry Cylinder {
                  height 0.06
                  radius 0.01
                }
              }
            ]
          }
          DEF A1_Transform Pose {
            translation 0.0315 0 0
            children [
              DEF A1 Shape {
                appearance PBRAppearance {
                  baseColor 0.898039 0.647059 0.0392157
                  metalness 0
                }
                geometry Box {
                  size 0.063 0.02 0.02
                }
              }
            ]
          }
          DEF L5J2 HingeJoint {
            jointParameters HingeJointParameters {
              axis 0 0 1
              anchor 0.063 0 0
            }
            device [
              DEF Servo12 RotationalMotor {
                name "Servo52"
              }
            ]
            endPoint Solid {
              translation 0.06300000000000001 -5.23795318344269e-18 0
              children [
                DEF A2_Transform Pose {
                  translation 0.045 0 0
                  children [
                    DEF A2 Shape {
                      appearance PBRAppearance {
                        baseColor 1 0.470588 0
                        metalness 0
                      }
                      geometry Box {
                        size 0.09 0.02 0.02
                      }
                    }
                  ]
                }
                DEF L5J3 HingeJoint {
                  jointParameters HingeJointParameters {
                    axis 0 0 1
                    anchor 0.09 0 0
                  }
                  device [
                    DEF Servo13 RotationalMotor {
                      name "Servo53"
                    }
                  ]
                  endPoint Solid {
                    translation 0.09 0 0
                    children [
                      DEF FootTransform Pose {
                        translation 0.215 0 0
                        children [
                          DEF L1FootSphere Shape {
                            appearance PBRAppearance {
                              baseColor 0.141176 0.121569 0.192157
                              roughness 1
                              metalness 0
                            }
                            geometry Sphere {
                              radius 0.015
                            }
                          }
                        ]
                      }
                      DEF A3_Transform Pose {
                        translation 0.1075 0 0
                        children [
                          DEF A3 Shape {
                            appearance PBRAppearance {
                              baseColor 0.14902 0.635294 0.411765
                              metalness 0
                            }
                            geometry Box {
                              size 0.215 0.02 0.02
                            }
                          }
                        ]
                      }
                      Shape {
                        appearance PBRAppearance {
                          baseColor 0.380392 0.207843 0.513726
                          metalness 0
                        }
                        geometry Cylinder {
                          height 0.025
                          radius 0.0125
                        }
                      }
                    ]
                    boundingObject USE FootTransform
                    physics Physics {
                    }
                  }
                }
                Shape {
                  appearance PBRAppearance {
                    baseColor 0.380392 0.207843 0.513726
                    metalness 0
                  }
                  geometry Cylinder {
                    height 0.025
                    radius 0.0125
                  }
                }
              ]
              boundingObject USE A2_Transform
              physics Physics {
              }
            }
          }
        ]
        name "solid(10)"
        boundingObject USE A1_Transform
        physics Physics {
        }
      }
    }
    DEF L4J1 HingeJoint {
      jointParameters HingeJointParameters {
        position 3.14
        axis 0 0 1
        anchor -0.1 0.15 0
      }
      device [
        RotationalMotor {
          name "Servo41"
        }
      ]
      endPoint Solid {
        translation -0.0998806 0.15 -1.42681e-05
        rotation 0.0005622220463405447 0.7071079756357186 0.707105363222997 3.140466234838101
        children [
          DEF L2MountServoTransform Pose {
            rotation 1 0 0 -1.5708
            children [
              DEF MountPoint Shape {
                appearance PBRAppearance {
                  baseColor 0.380392 0.207843 0.513726
                  metalness 0
                }
                geometry Cylinder {
                  height 0.06
                  radius 0.01
                }
              }
            ]
          }
          DEF A1_Transform Pose {
            translation 0.0315 0 0
            children [
              DEF A1 Shape {
                appearance PBRAppearance {
                  baseColor 0.898039 0.647059 0.0392157
                  metalness 0
                }
                geometry Box {
                  size 0.063 0.02 0.02
                }
              }
            ]
          }
          DEF L4J2 HingeJoint {
            jointParameters HingeJointParameters {
              axis 0 0 1
              anchor 0.063 0 0
            }
            device [
              DEF Servo12 RotationalMotor {
                name "Servo42"
              }
            ]
            endPoint Solid {
              translation 0.06300000000000001 -5.300841073157004e-18 0
              children [
                DEF A2_Transform Pose {
                  translation 0.045 0 0
                  children [
                    DEF A2 Shape {
                      appearance PBRAppearance {
                        baseColor 1 0.470588 0
                        metalness 0
                      }
                      geometry Box {
                        size 0.09 0.02 0.02
                      }
                    }
                  ]
                }
                DEF L4J3 HingeJoint {
                  jointParameters HingeJointParameters {
                    axis 0 0 1
                    anchor 0.09 0 0
                  }
                  device [
                    DEF Servo13 RotationalMotor {
                      name "Servo43"
                    }
                  ]
                  endPoint Solid {
                    translation 0.09 0 0
                    children [
                      DEF FootTransform Pose {
                        translation 0.215 0 0
                        children [
                          DEF L1FootSphere Shape {
                            appearance PBRAppearance {
                              baseColor 0.141176 0.121569 0.192157
                              roughness 1
                              metalness 0
                            }
                            geometry Sphere {
                              radius 0.015
                            }
                          }
                        ]
                      }
                      DEF A3_Transform Pose {
                        translation 0.1075 0 0
                        children [
                          DEF A3 Shape {
                            appearance PBRAppearance {
                              baseColor 0.14902 0.635294 0.411765
                              metalness 0
                            }
                            geometry Box {
                              size 0.215 0.02 0.02
                            }
                          }
                        ]
                      }
                      Shape {
                        appearance PBRAppearance {
                          baseColor 0.380392 0.207843 0.513726
                          metalness 0
                        }
                        geometry Cylinder {
                          height 0.025
                          radius 0.0125
                        }
                      }
                    ]
                    boundingObject USE FootTransform
                    physics Physics {
                    }
                  }
                }
                Shape {
                  appearance PBRAppearance {
                    baseColor 0.380392 0.207843 0.513726
                    metalness 0
                  }
                  geometry Cylinder {
                    height 0.025
                    radius 0.0125
                  }
                }
              ]
              boundingObject USE A2_Transform
              physics Physics {
              }
            }
          }
        ]
        name "solid(9)"
        boundingObject USE A1_Transform
        physics Physics {
        }
      }
    }
    DEF L3J1 HingeJoint {
      jointParameters HingeJointParameters {
        axis 0 0 1
        anchor 0.1 -0.15 0
      }
      device [
        RotationalMotor {
          name "Servo31"
        }
      ]
      endPoint Solid {
        translation 0.1 -0.15 -1.42681e-05
        rotation 0.9999999999992331 1.2262625356477944e-06 -1.7305524665346252e-07 1.5708000201914332
        children [
          DEF MountServoTransform Pose {
            rotation 1 0 0 -1.5708
            children [
              DEF MountPoint Shape {
                appearance PBRAppearance {
                  baseColor 0.380392 0.207843 0.513726
                  metalness 0
                }
                geometry Cylinder {
                  height 0.06
                  radius 0.01
                }
              }
            ]
          }
          DEF A1_Transform Pose {
            translation 0.0315 0 0
            children [
              DEF A1 Shape {
                appearance PBRAppearance {
                  baseColor 0.898039 0.647059 0.0392157
                  metalness 0
                }
                geometry Box {
                  size 0.063 0.02 0.02
                }
              }
            ]
          }
          DEF L3J2 HingeJoint {
            jointParameters HingeJointParameters {
              axis 0 0 1
              anchor 0.063 0 0
            }
            device [
              DEF Servo12 RotationalMotor {
                name "Servo32"
              }
            ]
            endPoint Solid {
              translation 0.06300000000000001 -5.291434384136743e-18 0
              children [
                DEF A2_Transform Pose {
                  translation 0.045 0 0
                  children [
                    DEF A2 Shape {
                      appearance PBRAppearance {
                        baseColor 1 0.470588 0
                        metalness 0
                      }
                      geometry Box {
                        size 0.09 0.02 0.02
                      }
                    }
                  ]
                }
                DEF L3J3 HingeJoint {
                  jointParameters HingeJointParameters {
                    axis 0 0 1
                    anchor 0.09 0 0
                  }
                  device [
                    DEF Servo13 RotationalMotor {
                      name "Servo33"
                    }
                  ]
                  endPoint Solid {
                    translation 0.09 0 0
                    children [
                      DEF FootTransform Pose {
                        translation 0.215 0 0
                        children [
                          DEF L1FootSphere Shape {
                            appearance PBRAppearance {
                              baseColor 0.141176 0.121569 0.192157
                              roughness 1
                              metalness 0
                            }
                            geometry Sphere {
                              radius 0.015
                            }
                          }
                        ]
                      }
                      DEF A3_Transform Pose {
                        translation 0.1075 0 0
                        children [
                          DEF A3 Shape {
                            appearance PBRAppearance {
                              baseColor 0.14902 0.635294 0.411765
                              metalness 0
                            }
                            geometry Box {
                              size 0.215 0.02 0.02
                            }
                          }
                        ]
                      }
                      Shape {
                        appearance PBRAppearance {
                          baseColor 0.380392 0.207843 0.513726
                          metalness 0
                        }
                        geometry Cylinder {
                          height 0.025
                          radius 0.0125
                        }
                      }
                    ]
                    boundingObject USE FootTransform
                    physics Physics {
                    }
                  }
                }
                Shape {
                  appearance PBRAppearance {
                    baseColor 0.380392 0.207843 0.513726
                    metalness 0
                  }
                  geometry Cylinder {
                    height 0.025
                    radius 0.0125
                  }
                }
              ]
              boundingObject USE A2_Transform
              physics Physics {
              }
            }
          }
        ]
        name "solid(8)"
        boundingObject USE A1_Transform
        physics Physics {
        }
      }
    }
    DEF L2J1 HingeJoint {
      jointParameters HingeJointParameters {
        axis 0 0 1
        anchor 0.1 0 0
      }
      device [
        RotationalMotor {
          name "Servo21"
        }
      ]
      endPoint Solid {
        translation 0.1 0 -1.4268099999999996e-05
        rotation 0.9999999999992331 1.2262625356281685e-06 -1.7305524664364954e-07 1.5708000201914332
        children [
          DEF MountServoTransform Pose {
            rotation 1 0 0 -1.5708
            children [
              DEF MountPoint Shape {
                appearance PBRAppearance {
                  baseColor 0.380392 0.207843 0.513726
                  metalness 0
                }
                geometry Cylinder {
                  height 0.06
                  radius 0.01
                }
              }
            ]
          }
          DEF A1_Transform Pose {
            translation 0.0315 0 0
            children [
              DEF A1 Shape {
                appearance PBRAppearance {
                  baseColor 0.898039 0.647059 0.0392157
                  metalness 0
                }
                geometry Box {
                  size 0.063 0.02 0.02
                }
              }
            ]
          }
          DEF L2J2 HingeJoint {
            jointParameters HingeJointParameters {
              axis 0 0 1
              anchor 0.063 0 0
            }
            device [
              DEF Servo12 RotationalMotor {
                name "Servo22"
              }
            ]
            endPoint Solid {
              translation 0.06300000000000001 -7.290964000244083e-18 0
              children [
                DEF A2_Transform Pose {
                  translation 0.045 0 0
                  children [
                    DEF A2 Shape {
                      appearance PBRAppearance {
                        baseColor 1 0.470588 0
                        metalness 0
                      }
                      geometry Box {
                        size 0.09 0.02 0.02
                      }
                    }
                  ]
                }
                DEF L2J3 HingeJoint {
                  jointParameters HingeJointParameters {
                    axis 0 0 1
                    anchor 0.09 0 0
                  }
                  device [
                    DEF Servo13 RotationalMotor {
                      name "Servo23"
                    }
                  ]
                  endPoint Solid {
                    translation 0.09 0 0
                    children [
                      DEF FootTransform Pose {
                        translation 0.215 0 0
                        children [
                          DEF L1FootSphere Shape {
                            appearance PBRAppearance {
                              baseColor 0.141176 0.121569 0.192157
                              roughness 1
                              metalness 0
                            }
                            geometry Sphere {
                              radius 0.015
                            }
                          }
                        ]
                      }
                      DEF A3_Transform Pose {
                        translation 0.1075 0 0
                        children [
                          DEF A3 Shape {
                            appearance PBRAppearance {
                              baseColor 0.14902 0.635294 0.411765
                              metalness 0
                            }
                            geometry Box {
                              size 0.215 0.02 0.02
                            }
                          }
                        ]
                      }
                      Shape {
                        appearance PBRAppearance {
                          baseColor 0.380392 0.207843 0.513726
                          metalness 0
                        }
                        geometry Cylinder {
                          height 0.025
                          radius 0.0125
                        }
                      }
                    ]
                    boundingObject USE FootTransform
                    physics Physics {
                    }
                  }
                }
                Shape {
                  appearance PBRAppearance {
                    baseColor 0.380392 0.207843 0.513726
                    metalness 0
                  }
                  geometry Cylinder {
                    height 0.025
                    radius 0.0125
                  }
                }
              ]
              boundingObject USE A2_Transform
              physics Physics {
              }
            }
          }
        ]
        name "solid(7)"
        boundingObject USE A1_Transform
        physics Physics {
        }
      }
    }
    DEF L1J1 HingeJoint {
      jointParameters HingeJointParameters {
        axis 0 0 1
        anchor 0.1 0.15 0
      }
      device [
        RotationalMotor {
          name "Servo11"
        }
      ]
      endPoint Solid {
        translation 0.1 0.15 -1.42681e-05
        rotation 0.9999999999992331 1.2262625356576075e-06 -1.7305524672215398e-07 1.5708000201914332
        children [
          DEF MountServoTransform Pose {
            rotation 1 0 0 -1.5708
            children [
              DEF MountPoint Shape {
                appearance PBRAppearance {
                  baseColor 0.380392 0.207843 0.513726
                  metalness 0
                }
                geometry Cylinder {
                  height 0.06
                  radius 0.01
                }
              }
            ]
          }
          DEF A1_Transform Pose {
            translation 0.0315 0 0
            children [
              DEF A1 Shape {
                appearance PBRAppearance {
                  baseColor 0.898039 0.647059 0.0392157
                  metalness 0
                }
                geometry Box {
                  size 0.063 0.02 0.02
                }
              }
            ]
          }
          DEF L1J2 HingeJoint {
            jointParameters HingeJointParameters {
              axis 0 0 1
              anchor 0.063 0 0
            }
            device [
              DEF Servo12 RotationalMotor {
                name "Servo12"
              }
            ]
            endPoint Solid {
              translation 0.06300000000000001 -4.9845251334003666e-18 0
              children [
                DEF A2_Transform Pose {
                  translation 0.045 0 0
                  children [
                    DEF A2 Shape {
                      appearance PBRAppearance {
                        baseColor 1 0.470588 0
                        metalness 0
                      }
                      geometry Box {
                        size 0.09 0.02 0.02
                      }
                    }
                  ]
                }
                DEF L1J3 HingeJoint {
                  jointParameters HingeJointParameters {
                    axis 0 0 1
                    anchor 0.09 0 0
                  }
                  device [
                    DEF Servo13 RotationalMotor {
                      name "Servo13"
                    }
                  ]
                  endPoint Solid {
                    translation 0.09 0 0
                    children [
                      DEF FootTransform Pose {
                        translation 0.215 0 0
                        children [
                          DEF L1FootSphere Shape {
                            appearance PBRAppearance {
                              baseColor 0.141176 0.121569 0.192157
                              roughness 1
                              metalness 0
                            }
                            geometry Sphere {
                              radius 0.015
                            }
                          }
                        ]
                      }
                      DEF A3_Transform Pose {
                        translation 0.1075 0 0
                        children [
                          DEF A3 Shape {
                            appearance PBRAppearance {
                              baseColor 0.14902 0.635294 0.411765
                              metalness 0
                            }
                            geometry Box {
                              size 0.215 0.02 0.02
                            }
                          }
                        ]
                      }
                      Shape {
                        appearance PBRAppearance {
                          baseColor 0.380392 0.207843 0.513726
                          metalness 0
                        }
                        geometry Cylinder {
                          height 0.025
                          radius 0.0125
                        }
                      }
                    ]
                    boundingObject USE FootTransform
                    physics Physics {
                    }
                  }
                }
                Shape {
                  appearance PBRAppearance {
                    baseColor 0.380392 0.207843 0.513726
                    metalness 0
                  }
                  geometry Cylinder {
                    height 0.025
                    radius 0.0125
                  }
                }
              ]
              boundingObject USE A2_Transform
              physics Physics {
              }
            }
          }
        ]
        name "solid(6)"
        boundingObject USE A1_Transform
        physics Physics {
        }
      }
    }
    DEF MainBody Shape {
      appearance PBRAppearance {
        baseColor 0.505882 0.239216 0.611765
        roughness 1
        metalness 0
      }
      geometry Box {
        size 0.2 0.3 0.05
      }
    }
  ]
    name IS name
    boundingObject USE MainBody
    physics Physics {
    }
  }
}
